Workbook

Sheet Ringkasan
A1: NEOTRACE Fase 3 & 4 — Rencana Kerja
A2: PT Neopangan Selaras Indonesia (Neofood) · Sauce Division · Fase 3: 6 minggu · Fase 4: 8 minggu
A4: Fase 3 — tujuan | B4: Menaikkan produktivitas gudang lewat wave picking, dan memberi manajemen angka yang bisa dipakai: KPI tenaga kerja, perputaran stok, barang mati
A5: Fase 3 — jadwal | B5: 11 Jan 2027 – 19 Feb 2027 · 6 minggu
A6: Fase 3 — lingkup | B6: Wave/zone/cluster picking, sesi kerja & KPI, klasifikasi ABC, turnover, slow moving, utilisasi gudang, ops scorecard
A7: Fase 4 — tujuan | B7: Menghentikan input ganda antara NEOTRACE dan ERP, serta memberi dasar perencanaan pembelian dari data konsumsi nyata
A8: Fase 4 — jadwal | B8: 08 Mar 2027 – 30 Apr 2027 · 8 minggu
A9: Fase 4 — lingkup | B9: Pola outbox/inbox, pemetaan ID, idempotensi & retry, monitor kesehatan sinkronisasi, riwayat konsumsi, musiman, peramalan, reorder point
A10: Jeda antar fase | B10: Fase 3 mulai 5 minggu setelah go-live Fase 2 (libur akhir tahun). Fase 4 mulai 2 minggu setelah Fase 3 stabil.
A11: Tim | B11: Fase 3: 1 Tech Lead, 2 Dev, 1 BA/QA. Fase 4: 1 Tech Lead, 1 Dev, 1 Integrator ERP, 1 BA/QA, 1 Planner Neofood
A12: KEPUTUSAN WAJIB SEBELUM FASE 4 | B12: Bila Neofood akan mengadopsi ERP penuh, Fase 4 mungkin tidak perlu dibangun — lihat sheet RAID baris R41. Keputusan ini harus diambil sebelum Fase 3 selesai.
A14: Milestone
A15: Fase | B15: Minggu | C15: Tanggal | D15: Milestone | E15: Kriteria selesai | F15: Status
A16: F3 | B16: 1 | C16: 11 Jan – 15 Jan 2027 | D16: Baseline produktivitas | E16: Waktu pick dan dock-to-stock sebelum wave picking terukur sebagai pembanding | F16: Belum
A17: F3 | B17: 2 | C17: 18 Jan – 22 Jan 2027 | D17: Wave picking jalan | E17: Gelombang dari 3+ batch terbit, terurut satu jalur, tote per batch | F17: Belum
A18: F3 | B18: 3 | C18: 25 Jan – 29 Jan 2027 | D18: Sesi kerja tercatat | E18: Clock in/out per tugas berjalan di HP tanpa menambah beban operator | F18: Belum
A19: F3 | B19: 4 | C19: 01 Feb – 05 Feb 2027 | D19: Dasbor analitik | E19: ABC, turnover, slow moving, utilisasi tampil di konsol desktop | F19: Belum
A20: F3 | B20: 5 | C20: 08 Feb – 12 Feb 2027 | D20: UAT lulus | E20: 0 defect Critical/High; wave picking terbukti tidak lebih lambat dari discrete | F20: Belum
A21: F3 | B21: 6 | C21: 15 Feb – 19 Feb 2027 | D21: Go-live + hypercare | E21: Wave picking dipakai penuh 5 hari kerja | F21: Belum
A22: F4 | B22: 1 | C22: 08 Mar – 12 Mar 2027 | D22: Kontrak data disepakati | E22: Pemilik data per entitas ditetapkan hitam di atas putih dengan tim ERP | F22: Belum
A23: F4 | B23: 2 | C23: 15 Mar – 19 Mar 2027 | D23: Endpoint & pemetaan | E23: Master item, partner, lokasi terpetakan dua arah di sandbox ERP | F23: Belum
A24: F4 | B24: 4 | C24: 29 Mar – 02 Apr 2027 | D24: Outbox jalan di sandbox | E24: GRN, DO, dan batch terkirim ke ERP sandbox tanpa dokumen ganda | F24: Belum
A25: F4 | B25: 5 | C25: 05 Apr – 09 Apr 2027 | D25: Peramalan pertama | E25: Forecast bulan berikut terbit; akurasi diukur terhadap realisasi historis | F25: Belum
A26: F4 | B26: 7 | C26: 19 Apr – 23 Apr 2027 | D26: UAT & rekonsiliasi | E26: Angka di ERP cocok dengan NEOTRACE untuk 1 bulan penuh data paralel | F26: Belum
A27: F4 | B27: 8 | C27: 26 Apr – 30 Apr 2027 | D27: Go-live + hypercare | E27: Input ganda dihentikan; monitor kesehatan sinkronisasi aktif | F27: Belum

Sheet Rencana Kerja
A1: Rencana Kerja Fase 3 & 4
A2: Effort dalam mandays. Kolom Fase memisahkan kedua fase.
A4: ID | B4: Fase | C4: Minggu | D4: Workstream | E4: Tugas | F4: Deliverable | G4: PIC | H4: Effort (md) | I4: Depends | J4: Status
A5: W01 | B5: F3 | C5: 1 | D5: Analisis | E5: Ukur baseline: waktu pick, jarak tempuh, dock-to-stock sebelum perubahan | F5: Laporan baseline | G5: BA/QA | H5: 2
A6: W02 | B6: F3 | C6: 1 | D6: Database | E6: Jalankan neotrace_phase3_delta.sql di staging | F6: Skema Fase 3 | G6: Tech Lead | H6: 0.5
A7: W03 | B7: F3 | C7: 1 | D7: Data | E7: Tetapkan zona pick dan aturan pengelompokan gelombang | F7: Aturan wave | G7: BA/QA | H7: 1.5 | I7: W01
A8: W04 | B8: F3 | C8: 1 | D8: Data | E8: Jalankan classify_abc() dan validasi hasil bersama planner | F8: Kelas ABC | G8: Tech Lead | H8: 1 | I8: W02
A9: W05 | B9: F3 | C9: 2 | D9: Backend | E9: Uji generate_wave untuk 3-5 batch, strategi BATCH dan ZONE | F9: Hasil uji | G9: Dev 1 | H9: 2 | I9: W02
A10: W06 | B10: F3 | C10: 2 | D10: Frontend | E10: Konsol desktop: bentuk gelombang, pilih batch, tugaskan petugas | F10: Layar wave | G10: Dev 1 | H10: 2.5 | I10: W05
A11: W07 | B11: F3 | C11: 2 | D11: Frontend | E11: Lembar kerja gelombang di HP: satu berhenti per rak, bagi ke tote | F11: Layar wave pick | G11: Dev 2 | H11: 3 | I11: W05
A12: W08 | B12: F3 | C12: 2 | D12: Proses | E12: Siapkan troli multi-tote dan penandaannya | F12: Troli siap | G12: Supervisor Gudang | H12: 1 | I12: W03
A13: W09 | B13: F3 | C13: 3 | D13: Frontend | E13: Clock in/out sesi kerja terintegrasi ke alur pick & put-away | F13: Modul sesi | G13: Dev 2 | H13: 2 | I13: W02
A14: W10 | B14: F3 | C14: 3 | D14: Backend | E14: Penanganan sesi menggantung & satu sesi terbuka per orang | F14: Aturan sesi | G14: Dev 2 | H14: 1 | I14: W09
A15: W11 | B15: F3 | C15: 3 | D15: Frontend | E15: Layar supervisor: siapa mengerjakan apa saat ini | F15: Papan sesi | G15: Dev 1 | H15: 2 | I15: W09
A16: W12 | B16: F3 | C16: 3 | D16: Proses | E16: Sosialisasi KPI: dipakai untuk coaching, bukan sanksi | F16: Materi sosialisasi | G16: BA/QA | H16: 1
A17: W13 | B17: F3 | C17: 4 | D17: Frontend | E17: Dasbor turnover, days on hand, slow moving | F17: Dashboard | G17: Dev 1 | H17: 2.5 | I17: W04
A18: W14 | B18: F3 | C18: 4 | D18: Frontend | E18: Dasbor utilisasi gudang & ops scorecard | F18: Dashboard | G18: Dev 1 | H18: 2 | I18: W13
A19: W15 | B19: F3 | C19: 4 | D19: Frontend | E19: Dasbor KPI tenaga kerja & kinerja gelombang | F19: Dashboard | G19: Dev 2 | H19: 2 | I19: W09
A20: W16 | B20: F3 | C20: 4 | D20: Analisis | E20: Interpretasi awal: barang mati & rekomendasi tindakan ke planner | F20: Laporan analitik | G20: BA/QA | H20: 1.5 | I20: W13
A21: W17 | B21: F3 | C21: 5 | D21: QA | E21: Eksekusi UAT Fase 3 | F21: Hasil UAT | G21: BA/QA | H21: 2.5 | I21: W15
A22: W18 | B22: F3 | C22: 5 | D22: Dev | E22: Perbaikan defect Critical & High | F22: Defect ditutup | G22: Dev 1 | H22: 2 | I22: W17
A23: W19 | B23: F3 | C23: 5 | D23: Analisis | E23: Bandingkan produktivitas wave vs discrete terhadap baseline | F23: Laporan pembanding | G23: BA/QA | H23: 1.5 | I23: W17
A24: W20 | B24: F3 | C24: 5 | D24: Database | E24: Deploy produksi + jadwal cron ABC bulanan | F24: Produksi siap | G24: Tech Lead | H24: 1 | I24: W18
A25: W21 | B25: F3 | C25: 6 | D25: Go-live | E25: Cutover wave picking | F25: Sistem live | G25: Semua | H25: 0.5 | I25: W20
A26: W22 | B26: F3 | C26: 6 | D26: Hypercare | E26: Pendampingan lantai gudang | F26: Log isu | G26: Dev 2 | H26: 3 | I26: W21
A27: W23 | B27: F3 | C27: 6 | D27: Hypercare | E27: Review pasca go-live + backlog Fase 4 | F27: Laporan penutup | G27: BA/QA | H27: 1 | I27: W22
A28: E01 | B28: F4 | C28: 1 | D28: Arsitektur | E28: Workshop kontrak data: tetapkan pemilik data per entitas dengan tim ERP | F28: Kontrak data | G28: Tech Lead | H28: 2
A29: E02 | B29: F4 | C29: 1 | D29: Arsitektur | E29: Tentukan arah & pemicu sinkronisasi per entitas | F29: Matriks integrasi | G29: Integrator ERP | H29: 1.5 | I29: E01
A30: E03 | B30: F4 | C30: 1 | D30: Database | E30: Jalankan neotrace_phase4_delta.sql di staging | F30: Skema Fase 4 | G30: Tech Lead | H30: 0.5
A31: E04 | B31: F4 | C31: 1 | D31: Integrasi | E31: Siapkan akses & kredensial ERP sandbox | F31: Akses sandbox | G31: Integrator ERP | H31: 1
A32: E05 | B32: F4 | C32: 2 | D32: Integrasi | E32: Pemetaan master: item, partner, lokasi, satuan | F32: entity_mappings terisi | G32: Integrator ERP | H32: 3 | I32: E04
A33: E06 | B33: F4 | C33: 2 | D33: Backend | E33: Worker sinkronisasi (Edge Function) dengan claim, ack, retry | F33: Worker | G33: Dev | H33: 2.5 | I33: E03
A34: E07 | B34: F4 | C34: 2 | D34: Backend | E34: Uji idempotensi: retry tidak menghasilkan dokumen ganda | F34: Hasil uji | G34: Dev | H34: 1.5 | I34: E06
A35: E08 | B35: F4 | C35: 3 | D35: Integrasi | E35: Kirim GRN ke ERP sandbox end-to-end | F35: GRN tersinkron | G35: Integrator ERP | H35: 2.5 | I35: E05,E06
A36: E09 | B36: F4 | C36: 3 | D36: Integrasi | E36: Kirim DO ke ERP sandbox end-to-end | F36: DO tersinkron | G36: Integrator ERP | H36: 2 | I36: E08
A37: E10 | B37: F4 | C37: 3 | D37: Frontend | E37: Monitor kesehatan sinkronisasi di konsol admin | F37: Layar monitor | G37: Dev | H37: 1.5 | I37: E06
A38: E11 | B38: F4 | C38: 4 | D38: Integrasi | E38: Kirim penutupan batch beserta HPP ke ERP | F38: Batch tersinkron | G38: Integrator ERP | H38: 2.5 | I38: E09
A39: E12 | B39: F4 | C39: 4 | D39: Integrasi | E39: Inbox: terima perubahan master item & partner dari ERP | F39: Inbox jalan | G39: Integrator ERP | H39: 2 | I39: E05
A40: E13 | B40: F4 | C40: 4 | D40: QA | E40: Skenario UAT integrasi termasuk kasus gagal & retry | F40: Skrip UAT | G40: BA/QA | H40: 2 | I40: E11
A41: E14 | B41: F4 | C41: 5 | D41: Data | E41: Bersihkan & validasi riwayat konsumsi untuk peramalan | F41: Data bersih | G41: BA/QA | H41: 2
...

Sheet Effort per Minggu
A1: Beban Kerja per Minggu
A2: Kapasitas 5 md per orang per minggu. Angka di atas 5 berarti overload.
A4: Fase | B4: Minggu | C4: Tanggal | D4: Tech Lead | E4: Dev 1 / Dev | F4: Dev 2 | G4: Integrator ERP | H4: BA/QA
A5: F3 | B5: 1 | C5: 11 Jan – 15 Jan 2027 | D5: =SUMIFS('Rencana Kerja'!$H$5:$H$53,'Rencana Kerja'!$B$5:$B$53,$A5,'Rencana Kerja'!$C$5:$C$53,$B5,'Rencana Kerja'!$G$5:$G$53,"Tech Lead") -> 1.5 | E5: =SUMIFS('Rencana Kerja'!$H$5:$H$53,'Rencana Kerja'!$B$5:$B$53,$A5,'Rencana Kerja'!$C$5:$C$53,$B5,'Rencana Kerja'!$G$5:$G$53,"Dev 1") -> 0 | F5: =SUMIFS('Rencana Kerja'!$H$5:$H$53,'Rencana Kerja'!$B$5:$B$53,$A5,'Rencana Kerja'!$C$5:$C$53,$B5,'Rencana Kerja'!$G$5:$G$53,"Dev 2") -> 0 | G5: =SUMIFS('Rencana Kerja'!$H$5:$H$53,'Rencana Kerja'!$B$5:$B$53,$A5,'Rencana Kerja'!$C$5:$C$53,$B5,'Rencana Kerja'!$G$5:$G$53,"Integrator ERP") -> 0 | H5: =SUMIFS('Rencana Kerja'!$H$5:$H$53,'Rencana Kerja'!$B$5:$B$53,$A5,'Rencana Kerja'!$C$5:$C$53,$B5,'Rencana Kerja'!$G$5:$G$53,"BA/QA") -> 3.5
A6: F3 | B6: 2 | C6: 18 Jan – 22 Jan 2027 | D6: =SUMIFS('Rencana Kerja'!$H$5:$H$53,'Rencana Kerja'!$B$5:$B$53,$A6,'Rencana Kerja'!$C$5:$C$53,$B6,'Rencana Kerja'!$G$5:$G$53,"Tech Lead") -> 0 | E6: =SUMIFS('Rencana Kerja'!$H$5:$H$53,'Rencana Kerja'!$B$5:$B$53,$A6,'Rencana Kerja'!$C$5:$C$53,$B6,'Rencana Kerja'!$G$5:$G$53,"Dev 1") -> 4.5 | F6: =SUMIFS('Rencana Kerja'!$H$5:$H$53,'Rencana Kerja'!$B$5:$B$53,$A6,'Rencana Kerja'!$C$5:$C$53,$B6,'Rencana Kerja'!$G$5:$G$53,"Dev 2") -> 3 | G6: =SUMIFS('Rencana Kerja'!$H$5:$H$53,'Rencana Kerja'!$B$5:$B$53,$A6,'Rencana Kerja'!$C$5:$C$53,$B6,'Rencana Kerja'!$G$5:$G$53,"Integrator ERP") -> 0 | H6: =SUMIFS('Rencana Kerja'!$H$5:$H$53,'Rencana Kerja'!$B$5:$B$53,$A6,'Rencana Kerja'!$C$5:$C$53,$B6,'Rencana Kerja'!$G$5:$G$53,"BA/QA") -> 0
A7: F3 | B7: 3 | C7: 25 Jan – 29 Jan 2027 | D7: =SUMIFS('Rencana Kerja'!$H$5:$H$53,'Rencana Kerja'!$B$5:$B$53,$A7,'Rencana Kerja'!$C$5:$C$53,$B7,'Rencana Kerja'!$G$5:$G$53,"Tech Lead") -> 0 | E7: =SUMIFS('Rencana Kerja'!$H$5:$H$53,'Rencana Kerja'!$B$5:$B$53,$A7,'Rencana Kerja'!$C$5:$C$53,$B7,'Rencana Kerja'!$G$5:$G$53,"Dev 1") -> 2 | F7: =SUMIFS('Rencana Kerja'!$H$5:$H$53,'Rencana Kerja'!$B$5:$B$53,$A7,'Rencana Kerja'!$C$5:$C$53,$B7,'Rencana Kerja'!$G$5:$G$53,"Dev 2") -> 3 | G7: =SUMIFS('Rencana Kerja'!$H$5:$H$53,'Rencana Kerja'!$B$5:$B$53,$A7,'Rencana Kerja'!$C$5:$C$53,$B7,'Rencana Kerja'!$G$5:$G$53,"Integrator ERP") -> 0 | H7: =SUMIFS('Rencana Kerja'!$H$5:$H$53,'Rencana Kerja'!$B$5:$B$53,$A7,'Rencana Kerja'!$C$5:$C$53,$B7,'Rencana Kerja'!$G$5:$G$53,"BA/QA") -> 1
A8: F3 | B8: 4 | C8: 01 Feb – 05 Feb 2027 | D8: =SUMIFS('Rencana Kerja'!$H$5:$H$53,'Rencana Kerja'!$B$5:$B$53,$A8,'Rencana Kerja'!$C$5:$C$53,$B8,'Rencana Kerja'!$G$5:$G$53,"Tech Lead") -> 0 | E8: =SUMIFS('Rencana Kerja'!$H$5:$H$53,'Rencana Kerja'!$B$5:$B$53,$A8,'Rencana Kerja'!$C$5:$C$53,$B8,'Rencana Kerja'!$G$5:$G$53,"Dev 1") -> 4.5 | F8: =SUMIFS('Rencana Kerja'!$H$5:$H$53,'Rencana Kerja'!$B$5:$B$53,$A8,'Rencana Kerja'!$C$5:$C$53,$B8,'Rencana Kerja'!$G$5:$G$53,"Dev 2") -> 2 | G8: =SUMIFS('Rencana Kerja'!$H$5:$H$53,'Rencana Kerja'!$B$5:$B$53,$A8,'Rencana Kerja'!$C$5:$C$53,$B8,'Rencana Kerja'!$G$5:$G$53,"Integrator ERP") -> 0 | H8: =SUMIFS('Rencana Kerja'!$H$5:$H$53,'Rencana Kerja'!$B$5:$B$53,$A8,'Rencana Kerja'!$C$5:$C$53,$B8,'Rencana Kerja'!$G$5:$G$53,"BA/QA") -> 1.5
A9: F3 | B9: 5 | C9: 08 Feb – 12 Feb 2027 | D9: =SUMIFS('Rencana Kerja'!$H$5:$H$53,'Rencana Kerja'!$B$5:$B$53,$A9,'Rencana Kerja'!$C$5:$C$53,$B9,'Rencana Kerja'!$G$5:$G$53,"Tech Lead") -> 1 | E9: =SUMIFS('Rencana Kerja'!$H$5:$H$53,'Rencana Kerja'!$B$5:$B$53,$A9,'Rencana Kerja'!$C$5:$C$53,$B9,'Rencana Kerja'!$G$5:$G$53,"Dev 1") -> 2 | F9: =SUMIFS('Rencana Kerja'!$H$5:$H$53,'Rencana Kerja'!$B$5:$B$53,$A9,'Rencana Kerja'!$C$5:$C$53,$B9,'Rencana Kerja'!$G$5:$G$53,"Dev 2") -> 0 | G9: =SUMIFS('Rencana Kerja'!$H$5:$H$53,'Rencana Kerja'!$B$5:$B$53,$A9,'Rencana Kerja'!$C$5:$C$53,$B9,'Rencana Kerja'!$G$5:$G$53,"Integrator ERP") -> 0 | H9: =SUMIFS('Rencana Kerja'!$H$5:$H$53,'Rencana Kerja'!$B$5:$B$53,$A9,'Rencana Kerja'!$C$5:$C$53,$B9,'Rencana Kerja'!$G$5:$G$53,"BA/QA") -> 4
A10: F3 | B10: 6 | C10: 15 Feb – 19 Feb 2027 | D10: =SUMIFS('Rencana Kerja'!$H$5:$H$53,'Rencana Kerja'!$B$5:$B$53,$A10,'Rencana Kerja'!$C$5:$C$53,$B10,'Rencana Kerja'!$G$5:$G$53,"Tech Lead") -> 0 | E10: =SUMIFS('Rencana Kerja'!$H$5:$H$53,'Rencana Kerja'!$B$5:$B$53,$A10,'Rencana Kerja'!$C$5:$C$53,$B10,'Rencana Kerja'!$G$5:$G$53,"Dev 1") -> 0 | F10: =SUMIFS('Rencana Kerja'!$H$5:$H$53,'Rencana Kerja'!$B$5:$B$53,$A10,'Rencana Kerja'!$C$5:$C$53,$B10,'Rencana Kerja'!$G$5:$G$53,"Dev 2") -> 3 | G10: =SUMIFS('Rencana Kerja'!$H$5:$H$53,'Rencana Kerja'!$B$5:$B$53,$A10,'Rencana Kerja'!$C$5:$C$53,$B10,'Rencana Kerja'!$G$5:$G$53,"Integrator ERP") -> 0 | H10: =SUMIFS('Rencana Kerja'!$H$5:$H$53,'Rencana Kerja'!$B$5:$B$53,$A10,'Rencana Kerja'!$C$5:$C$53,$B10,'Rencana Kerja'!$G$5:$G$53,"BA/QA") -> 1
A11: F4 | B11: 1 | C11: 08 Mar – 12 Mar 2027 | D11: =SUMIFS('Rencana Kerja'!$H$5:$H$53,'Rencana Kerja'!$B$5:$B$53,$A11,'Rencana Kerja'!$C$5:$C$53,$B11,'Rencana Kerja'!$G$5:$G$53,"Tech Lead") -> 2.5 | E11: =SUMIFS('Rencana Kerja'!$H$5:$H$53,'Rencana Kerja'!$B$5:$B$53,$A11,'Rencana Kerja'!$C$5:$C$53,$B11,'Rencana Kerja'!$G$5:$G$53,"Dev") -> 0 | F11: =SUMIFS('Rencana Kerja'!$H$5:$H$53,'Rencana Kerja'!$B$5:$B$53,$A11,'Rencana Kerja'!$C$5:$C$53,$B11,'Rencana Kerja'!$G$5:$G$53,"Dev 2") -> 0 | G11: =SUMIFS('Rencana Kerja'!$H$5:$H$53,'Rencana Kerja'!$B$5:$B$53,$A11,'Rencana Kerja'!$C$5:$C$53,$B11,'Rencana Kerja'!$G$5:$G$53,"Integrator ERP") -> 2.5 | H11: =SUMIFS('Rencana Kerja'!$H$5:$H$53,'Rencana Kerja'!$B$5:$B$53,$A11,'Rencana Kerja'!$C$5:$C$53,$B11,'Rencana Kerja'!$G$5:$G$53,"BA/QA") -> 0
A12: F4 | B12: 2 | C12: 15 Mar – 19 Mar 2027 | D12: =SUMIFS('Rencana Kerja'!$H$5:$H$53,'Rencana Kerja'!$B$5:$B$53,$A12,'Rencana Kerja'!$C$5:$C$53,$B12,'Rencana Kerja'!$G$5:$G$53,"Tech Lead") -> 0 | E12: =SUMIFS('Rencana Kerja'!$H$5:$H$53,'Rencana Kerja'!$B$5:$B$53,$A12,'Rencana Kerja'!$C$5:$C$53,$B12,'Rencana Kerja'!$G$5:$G$53,"Dev") -> 4 | F12: =SUMIFS('Rencana Kerja'!$H$5:$H$53,'Rencana Kerja'!$B$5:$B$53,$A12,'Rencana Kerja'!$C$5:$C$53,$B12,'Rencana Kerja'!$G$5:$G$53,"Dev 2") -> 0 | G12: =SUMIFS('Rencana Kerja'!$H$5:$H$53,'Rencana Kerja'!$B$5:$B$53,$A12,'Rencana Kerja'!$C$5:$C$53,$B12,'Rencana Kerja'!$G$5:$G$53,"Integrator ERP") -> 3 | H12: =SUMIFS('Rencana Kerja'!$H$5:$H$53,'Rencana Kerja'!$B$5:$B$53,$A12,'Rencana Kerja'!$C$5:$C$53,$B12,'Rencana Kerja'!$G$5:$G$53,"BA/QA") -> 0
A13: F4 | B13: 3 | C13: 22 Mar – 26 Mar 2027 | D13: =SUMIFS('Rencana Kerja'!$H$5:$H$53,'Rencana Kerja'!$B$5:$B$53,$A13,'Rencana Kerja'!$C$5:$C$53,$B13,'Rencana Kerja'!$G$5:$G$53,"Tech Lead") -> 0 | E13: =SUMIFS('Rencana Kerja'!$H$5:$H$53,'Rencana Kerja'!$B$5:$B$53,$A13,'Rencana Kerja'!$C$5:$C$53,$B13,'Rencana Kerja'!$G$5:$G$53,"Dev") -> 1.5 | F13: =SUMIFS('Rencana Kerja'!$H$5:$H$53,'Rencana Kerja'!$B$5:$B$53,$A13,'Rencana Kerja'!$C$5:$C$53,$B13,'Rencana Kerja'!$G$5:$G$53,"Dev 2") -> 0 | G13: =SUMIFS('Rencana Kerja'!$H$5:$H$53,'Rencana Kerja'!$B$5:$B$53,$A13,'Rencana Kerja'!$C$5:$C$53,$B13,'Rencana Kerja'!$G$5:$G$53,"Integrator ERP") -> 4.5 | H13: =SUMIFS('Rencana Kerja'!$H$5:$H$53,'Rencana Kerja'!$B$5:$B$53,$A13,'Rencana Kerja'!$C$5:$C$53,$B13,'Rencana Kerja'!$G$5:$G$53,"BA/QA") -> 0
A14: F4 | B14: 4 | C14: 29 Mar – 02 Apr 2027 | D14: =SUMIFS('Rencana Kerja'!$H$5:$H$53,'Rencana Kerja'!$B$5:$B$53,$A14,'Rencana Kerja'!$C$5:$C$53,$B14,'Rencana Kerja'!$G$5:$G$53,"Tech Lead") -> 0 | E14: =SUMIFS('Rencana Kerja'!$H$5:$H$53,'Rencana Kerja'!$B$5:$B$53,$A14,'Rencana Kerja'!$C$5:$C$53,$B14,'Rencana Kerja'!$G$5:$G$53,"Dev") -> 0 | F14: =SUMIFS('Rencana Kerja'!$H$5:$H$53,'Rencana Kerja'!$B$5:$B$53,$A14,'Rencana Kerja'!$C$5:$C$53,$B14,'Rencana Kerja'!$G$5:$G$53,"Dev 2") -> 0 | G14: =SUMIFS('Rencana Kerja'!$H$5:$H$53,'Rencana Kerja'!$B$5:$B$53,$A14,'Rencana Kerja'!$C$5:$C$53,$B14,'Rencana Kerja'!$G$5:$G$53,"Integrator ERP") -> 4.5 | H14: =SUMIFS('Rencana Kerja'!$H$5:$H$53,'Rencana Kerja'!$B$5:$B$53,$A14,'Rencana Kerja'!$C$5:$C$53,$B14,'Rencana Kerja'!$G$5:$G$53,"BA/QA") -> 2
A15: F4 | B15: 5 | C15: 05 Apr – 09 Apr 2027 | D15: =SUMIFS('Rencana Kerja'!$H$5:$H$53,'Rencana Kerja'!$B$5:$B$53,$A15,'Rencana Kerja'!$C$5:$C$53,$B15,'Rencana Kerja'!$G$5:$G$53,"Tech Lead") -> 0 | E15: =SUMIFS('Rencana Kerja'!$H$5:$H$53,'Rencana Kerja'!$B$5:$B$53,$A15,'Rencana Kerja'!$C$5:$C$53,$B15,'Rencana Kerja'!$G$5:$G$53,"Dev") -> 4 | F15: =SUMIFS('Rencana Kerja'!$H$5:$H$53,'Rencana Kerja'!$B$5:$B$53,$A15,'Rencana Kerja'!$C$5:$C$53,$B15,'Rencana Kerja'!$G$5:$G$53,"Dev 2") -> 0 | G15: =SUMIFS('Rencana Kerja'!$H$5:$H$53,'Rencana Kerja'!$B$5:$B$53,$A15,'Rencana Kerja'!$C$5:$C$53,$B15,'Rencana Kerja'!$G$5:$G$53,"Integrator ERP") -> 0 | H15: =SUMIFS('Rencana Kerja'!$H$5:$H$53,'Rencana Kerja'!$B$5:$B$53,$A15,'Rencana Kerja'!$C$5:$C$53,$B15,'Rencana Kerja'!$G$5:$G$53,"BA/QA") -> 2
A16: F4 | B16: 6 | C16: 12 Apr – 16 Apr 2027 | D16: =SUMIFS('Rencana Kerja'!$H$5:$H$53,'Rencana Kerja'!$B$5:$B$53,$A16,'Rencana Kerja'!$C$5:$C$53,$B16,'Rencana Kerja'!$G$5:$G$53,"Tech Lead") -> 0 | E16: =SUMIFS('Rencana Kerja'!$H$5:$H$53,'Rencana Kerja'!$B$5:$B$53,$A16,'Rencana Kerja'!$C$5:$C$53,$B16,'Rencana Kerja'!$G$5:$G$53,"Dev") -> 1 | F16: =SUMIFS('Rencana Kerja'!$H$5:$H$53,'Rencana Kerja'!$B$5:$B$53,$A16,'Rencana Kerja'!$C$5:$C$53,$B16,'Rencana Kerja'!$G$5:$G$53,"Dev 2") -> 0 | G16: =SUMIFS('Rencana Kerja'!$H$5:$H$53,'Rencana Kerja'!$B$5:$B$53,$A16,'Rencana Kerja'!$C$5:$C$53,$B16,'Rencana Kerja'!$G$5:$G$53,"Integrator ERP") -> 1.5 | H16: =SUMIFS('Rencana Kerja'!$H$5:$H$53,'Rencana Kerja'!$B$5:$B$53,$A16,'Rencana Kerja'!$C$5:$C$53,$B16,'Rencana Kerja'!$G$5:$G$53,"BA/QA") -> 2
A17: F4 | B17: 7 | C17: 19 Apr – 23 Apr 2027 | D17: =SUMIFS('Rencana Kerja'!$H$5:$H$53,'Rencana Kerja'!$B$5:$B$53,$A17,'Rencana Kerja'!$C$5:$C$53,$B17,'Rencana Kerja'!$G$5:$G$53,"Tech Lead") -> 0 | E17: =SUMIFS('Rencana Kerja'!$H$5:$H$53,'Rencana Kerja'!$B$5:$B$53,$A17,'Rencana Kerja'!$C$5:$C$53,$B17,'Rencana Kerja'!$G$5:$G$53,"Dev") -> 2.5 | F17: =SUMIFS('Rencana Kerja'!$H$5:$H$53,'Rencana Kerja'!$B$5:$B$53,$A17,'Rencana Kerja'!$C$5:$C$53,$B17,'Rencana Kerja'!$G$5:$G$53,"Dev 2") -> 0 | G17: =SUMIFS('Rencana Kerja'!$H$5:$H$53,'Rencana Kerja'!$B$5:$B$53,$A17,'Rencana Kerja'!$C$5:$C$53,$B17,'Rencana Kerja'!$G$5:$G$53,"Integrator ERP") -> 1 | H17: =SUMIFS('Rencana Kerja'!$H$5:$H$53,'Rencana Kerja'!$B$5:$B$53,$A17,'Rencana Kerja'!$C$5:$C$53,$B17,'Rencana Kerja'!$G$5:$G$53,"BA/QA") -> 3
A18: F4 | B18: 8 | C18: 26 Apr – 30 Apr 2027 | D18: =SUMIFS('Rencana Kerja'!$H$5:$H$53,'Rencana Kerja'!$B$5:$B$53,$A18,'Rencana Kerja'!$C$5:$C$53,$B18,'Rencana Kerja'!$G$5:$G$53,"Tech Lead") -> 0 | E18: =SUMIFS('Rencana Kerja'!$H$5:$H$53,'Rencana Kerja'!$B$5:$B$53,$A18,'Rencana Kerja'!$C$5:$C$53,$B18,'Rencana Kerja'!$G$5:$G$53,"Dev") -> 3 | F18: =SUMIFS('Rencana Kerja'!$H$5:$H$53,'Rencana Kerja'!$B$5:$B$53,$A18,'Rencana Kerja'!$C$5:$C$53,$B18,'Rencana Kerja'!$G$5:$G$53,"Dev 2") -> 0 | G18: =SUMIFS('Rencana Kerja'!$H$5:$H$53,'Rencana Kerja'!$B$5:$B$53,$A18,'Rencana Kerja'!$C$5:$C$53,$B18,'Rencana Kerja'!$G$5:$G$53,"Integrator ERP") -> 0 | H18: =SUMIFS('Rencana Kerja'!$H$5:$H$53,'Rencana Kerja'!$B$5:$B$53,$A18,'Rencana Kerja'!$C$5:$C$53,$B18,'Rencana Kerja'!$G$5:$G$53,"BA/QA") -> 1.5
A20: Pada Fase 4 kolom 'Dev 1 / Dev' berisi satu developer. Tugas ber-PIC 'Semua', 'Supervisor Gudang', dan 'Planner Neofood' tidak masuk kolom di atas.

Sheet RAID
A1: RAID Log — Fase 3 & 4
A2: R Risiko · A Asumsi · I Isu · D Dependensi
A4: ID | B4: Tipe | C4: Uraian | D4: Dampak | E4: Prob. | F4: Mitigasi / tindakan | G4: Owner | H4: Fase
A5: R31 | B5: Risiko | C5: Wave picking justru lebih lambat karena troli multi-tote sulit di lorong sempit | D5: Tinggi | E5: Sedang | F5: Ukur baseline dulu (W01); uji satu lorong sebelum diterapkan penuh; siapkan opsi kembali ke discrete | G5: BA/QA | H5: F3
A6: R32 | B6: Risiko | C6: KPI individu dipakai untuk menekan atau menyanksi petugas | D6: Tinggi | E6: Sedang | F6: Sosialisasi eksplisit (W12); tampilkan KPI tim sebagai default, individu hanya untuk supervisor | G6: PO Neofood | H6: F3
A7: R33 | B7: Risiko | C7: Bahan antar tote tertukar di troli | D7: Tinggi | E7: Sedang | F7: Kode tote dicetak besar; konfirmasi scan tetap per baris; audit acak minggu pertama | G7: Dev 2 | H7: F3
A8: R34 | B8: Risiko | C8: Klasifikasi ABC salah karena data pemakaian belum 12 bulan penuh | D8: Sedang | E8: Tinggi | F8: Tandai hasil sebagai indikatif sampai data 12 bulan tersedia; validasi manual dengan planner | G8: Tech Lead | H8: F3
A9: R41 | B9: Risiko | C9: Fase 4 membangun ulang fungsi yang sudah ada di ERP | D9: Tinggi | E9: Tinggi | F9: KEPUTUSAN STRATEGIS: bila Neofood mengadopsi ERP penuh, batalkan Fase 4 dan migrasikan. Putuskan sebelum Fase 3 selesai. | G9: PO Neofood | H9: F4
A10: R42 | B10: Risiko | C10: Dokumen ganda di ERP akibat retry | D10: Tinggi | E10: Sedang | F10: Idempotency_key + entity_mappings; uji khusus E07 sebelum menyentuh produksi | G10: Dev | H10: F4
A11: R43 | B11: Risiko | C11: Dua sistem sama-sama merasa memiliki data yang sama | D11: Tinggi | E11: Sedang | F11: Kontrak data tertulis (E01) menetapkan satu pemilik per entitas sebelum satu baris kode ditulis | G11: Tech Lead | H11: F4
A12: R44 | B12: Risiko | C12: Peramalan dipakai sebagai angka perencanaan padahal datanya belum cukup | D12: Sedang | E12: Tinggi | F12: Tampilkan MAPE di layar; sembunyikan saran reorder untuk item dengan data < 12 bulan | G12: Planner Neofood | H12: F4
A13: R45 | B13: Risiko | C13: Antrean sinkronisasi menumpuk tanpa disadari | D13: Sedang | E13: Sedang | F13: Monitor v_sync_health + notifikasi CRITICAL saat status DEAD; cek harian saat hypercare | G13: Dev | H13: F4
A14: A31 | B14: Asumsi | C14: Fase 2 stabil dan put-away serta picking sudah jadi kebiasaan | D14: Tinggi | E14: - | F14: Bila masih banyak fallback manual, Fase 3 ditunda | G14: PO Neofood | H14: F3
A15: A41 | B15: Asumsi | C15: ERP tujuan punya API yang bisa menerima dokumen dari luar | D15: Tinggi | E15: - | F15: Belum diverifikasi. Konfirmasi ke tim ERP sebelum kickoff Fase 4 | G15: Integrator ERP | H15: F4
... A19: D42 | B19: Dependensi | C19: Data konsumsi minimal 12 bulan dari Fase 1 | D19: Tinggi | E19: - | F19: Fase 1 mulai Agu 2026, jadi data 12 bulan baru lengkap Agu 2027 — peramalan awal bersifat indikatif | G19: Planner Neofood | H19: F4

Sheet Exit Criteria
A1: Kriteria Go-Live Fase 3 & 4
A2: Semua baris wajib Ya sebelum cutover masing-masing fase.
A4: Fase | B4: No | C4: Kriteria | D4: Bukti | E4: Penanggung jawab | F4: Terpenuhi
A5: F3 | B5: 1 | C5: Wave picking terbukti tidak lebih lambat dari discrete | D5: Laporan pembanding vs baseline | E5: BA/QA
A6: F3 | B6: 2 | C6: 0 kejadian bahan tertukar antar tote pada uji coba | D6: Audit acak | E6: Supervisor Gudang
A7: F3 | B7: 3 | C7: Sosialisasi KPI selesai dan disepakati sebagai alat coaching | D7: Berita acara sosialisasi | E7: PO Neofood
A8: F3 | B8: 4 | C8: Klasifikasi ABC divalidasi planner | D8: Daftar ABC bertanda tangan | E8: Planner Neofood
A9: F3 | B9: 5 | C9: 0 defect Critical/High terbuka | D9: Defect log | E9: BA/QA
A10: F4 | B10: 1 | C10: Kontrak data disepakati tertulis dengan tim ERP | D10: Dokumen kontrak data | E10: Tech Lead
A11: F4 | B11: 2 | C11: Uji idempotensi lulus: 0 dokumen ganda pada 100 retry | D11: Hasil uji | E11: Dev
A12: F4 | B12: 3 | C12: Rekonsiliasi 1 bulan paralel cocok 100% untuk GRN, DO, dan batch | D12: Laporan rekonsiliasi | E12: Finance Neofood
A13: F4 | B13: 4 | C13: Prosedur intervensi manual untuk pesan DEAD disepakati | D13: Prosedur tertulis | E13: Tech Lead
A14: F4 | B14: 5 | C14: Akurasi peramalan diukur dan batas pemakaiannya disepakati | D14: Laporan MAPE | E14: Planner Neofood
A15: F4 | B15: 6 | C15: Serah terima ke tim internal Neofood selesai | D15: Dokumen serah terima | E15: BA/QA
